Workbook

Sheet ⚙ LISTAS
A1: MEMBROS | B1: CURSOS | C1: FUNCOES | D1: TIPOS | E1: ACTOS | F1: RES_PRE | G1: RES_DEF | H1: MESES | I1: CANAIS | J1: ESTADOS | L1: VLOOKUP_KEY | M1: FUNCAO | N1: TIPO | O1: VALOR_BRUTO | P1: UNIQUE_DOCENTES
A2: Manuel Octávio Isaac Spínola | B2: Contabilidade e Gestão / CSH | C2: Presidente de Júri | D2: Individual | E2: Defesa | F2: Aprovado | G2: Reprovado (0-9) | H2: Fev/2026 | I2: Transferência Bancária | J2: PAGO | L2: Presidente de Júri|Individual | M2: Presidente de Júri | N2: Individual | O2: 20000 | P2: Manuel Octávio Isaac Spínola
A3: Ideleichy Lombillo Rivero | B3: Ensino Primário / CSH | C3: 1º Vogal Arguente | D3: Dupla | E3: Pré-Defesa | F3: Reprovado | G3: 10 | H3: Mar/2026 | I3: Numerário | J3: EM ATRASO | L3: Presidente de Júri|Dupla | M3: Presidente de Júri | N3: Dupla | O3: 27500 | P3: Ideleichy Lombillo Rivero
A4: Elizabeth González | B4: Agronomia / Engenharias e Tecnologias | C4: 2º Vogal Tutor/Orientador | F4: Pendente | G4: 11 | H4: Abr/2026 | I4: Cheque | J4: PARCIAL | L4: 1º Vogal Arguente|Individual | M4: 1º Vogal Arguente | N4: Individual | O4: 20000 | P4: Elizabeth González
A5: Domingos Lunga | B5: Enfermagem / Ciências da Saúde | C5: Co-tutor | F5: Condicionado | G5: 12 | H5: Mai/2026 | I5: Multicaixa | J5: ANULADO | L5: 1º Vogal Arguente|Dupla | M5: 1º Vogal Arguente | N5: Dupla | O5: 27500 | P5: Domingos Lunga
A6: José Fernando Manuel | B6: Todos os Cursos (Especial Ph.D.) | C6: Secretário | G6: 13 | H6: Jun/2026 | L6: 2º Vogal Tutor/Orientador|Individual | M6: 2º Vogal Tutor/Orientador | N6: Individual | O6: 80000 | P6: José Fernando Manuel
A7: Walquiria Chissimo | G7: 14 | H7: Jul/2026 | L7: 2º Vogal Tutor/Orientador|Dupla | M7: 2º Vogal Tutor/Orientador | N7: Dupla | O7: 104000 | P7: Walquiria Chissimo
A8: Félix Palau | G8: 15 | H8: Ago/2026 | L8: Co-tutor|Individual | M8: Co-tutor | N8: Individual | O8: 40000 | P8: Félix Palau
A9: Marilda Augusto | G9: 16 | H9: Set/2026 | L9: Co-tutor|Dupla | M9: Co-tutor | N9: Dupla | O9: 72000 | P9: Marilda Augusto
A10: José Monteiro | G10: 17 | H10: Out/2026 | L10: Secretário|Individual | M10: Secretário | N10: Individual | O10: 10000 | P10: José Monteiro
A11: Domingos Ngando | G11: 18 | H11: Nov/2026 | L11: Secretário|Dupla | M11: Secretário | N11: Dupla | O11: 15000 | P11: Domingos Ngando
G12: 19 | H12: Dez/2026
G13: 20

Sheet 📋 CAPA
B2: REPÚBLICA DE ANGOLA — INSTITUTO SUPERIOR POLITÉCNICO DO LIBOLO (ISPTLO)
B3: MAPA DE CONTROLO FINANCEIRO — PAGAMENTOS DE JÚRI DE TFC | Versão 3.0
B5: ⚠ NOVIDADE v3.0: Retenção IRT 6,5% calculada sobre o TOTAL MENSAL POR DOCENTE — não por sessão individual
B7: Instituição: | C7: Instituto Superior Politécnico do Libolo (ISPTLO)
B8: Unidade Gestora: | C8: Departamento de Administração e Serviços Gerais — Tesouraria
B9: Base Legal: | C9: D.P. nº 191/18 (ECDES) | Lei nº 7/15 (LGT) | C.I.R.T. Lei nº 19/14 Art.º 67 | IRT: 6,5%
B10: Responsável Actual: | C10: [Nome e Cargo — Responsável da Tesouraria]
B11: Período de Ref.: | C11: [Mês/Ano — ex.: Mai/2026]
B12: Versão: | C12: 3.0 — Arquitectura IRT acumulada por docente/mês
B13: Data de Emissão: | C13: 01/05/2026
B14: Aprovado por: | C14: [Nome, Grau, Cargo]
B15: Periodicidade: | C15: Actualização contínua | Reporte: último dia útil de cada mês
B17: ESTRUTURA DO FICHEIRO
B18: ⚙ LISTAS | C18: Folha oculta — fontes das listas suspensas e tabela VLOOKUP
B19: 📋 CAPA | C19: Identificação institucional, metadados e instruções
B20: 📘 TABELA_SUBSÍDIOS | C20: Matriz de valores fixos por Função + Tipo — base do VLOOKUP
B21: 👥 MEMBROS_JÚRI | C21: Registo de membros com hierarquia científica ISPTLO
B22: 📝 REGISTO_JÚRIS | C22: Data entry operacional — pré-defesas e defesas, listas suspensas
B23: 💰 LANÇAMENTOS | C23: Detalhe por sessão: valores brutos sem IRT (livro de razão)
B24: 🧾 RESUMO_IRT | C24: ⭐ FOLHA CRÍTICA: IRT calculado sobre total mensal por docente
B25: 📊 DASHBOARD | C25: Painel executivo consolidado — totais, AGT, gráficos
B27: INSTRUÇÕES CRÍTICAS
B28: 1. Campos com texto AZUL = dados de entrada (input). Fórmulas a preto — NÃO alterar.
B29: 2. LANÇAMENTOS: registe cada participação individual. O VLOOKUP calcula o valor automaticamente.
B30: 3. RESUMO_IRT: é aqui que se calcula o IRT. Um docente tem UMA linha por mês — IRT sobre o TOTAL.
B31: 4. Nunca aplique IRT em LANÇAMENTOS — a retenção incide apenas sobre o total mensal (RESUMO_IRT).
B32: 5. Partilhe o ficheiro com Vice-Presidência Académica no último dia útil de cada mês (Acordo 1.3).
B33: 6. Campos [A PREENCHER] em amarelo devem ser completados antes da distribuição.

Sheet 📘 TABELA_SUBSÍDIOS
B2: REPÚBLICA DE ANGOLA — INSTITUTO SUPERIOR POLITÉCNICO DO LIBOLO (ISPTLO)
B3: TABELA DE SUBSÍDIOS — JÚRI DE TFC | Fontes: Ofício 009/25 + Emenda DASG 023/2025
B5: Fonte: Ofício nº 009/25 + Emenda DASG nº 023/2025 (12/02/2025) | IRT: Lei nº 19/14 (C.I.R.T.) Art.º 67 | ECDES: D.P. nº 191/18
B7: A. MATRIZ DE SUBSÍDIOS POR FUNÇÃO E TIPO DE DEFESA (Base para VLOOKUP automático em LANÇAMENTOS)
B8: Função no Júri | C8: Individual Bruto (Kz) | D8: Individual IRT 6,5% | E8: Individual Líquido (Kz) | F8: Dupla Bruto (Kz) | G8: Dupla IRT 6,5% | H8: Dupla Líquido (Kz) | I8: Observação / Norma
B9: Presidente de Júri | C9: 20000 | D9: =C9*0.065 -> 1300 | E9: =C9-D9 -> 18700 | F9: 27500 | G9: =F9*0.065 -> 1787.5 | H9: =F9-G9 -> 25712.5 | I9: PhD obrigatório — ECDES art.º 8 | D.P. nº 191/18
B10: 1º Vogal Arguente | C10: 20000 | D10: =C10*0.065 -> 1300 | E10: =C10-D10 -> 18700 | F10: 27500 | G10: =F10*0.065 -> 1787.5 | H10: =F10-G10 -> 25712.5 | I10: Mestre ou superior
B11: 2º Vogal Tutor/Orientador | C11: 80000 | D11: =C11*0.065 -> 5200 | E11: =C11-D11 -> 74800 | F11: 104000 | G11: =F11*0.065 -> 6760 | H11: =F11-G11 -> 97240 | I11: Varia por tipo — Ofício 009/25 + Emenda DASG
B12: Co-tutor (se designado) | C12: 40000 | D12: =C12*0.065 -> 2600 | E12: =C12-D12 -> 37400 | F12: 72000 | G12: =F12*0.065 -> 4680 | H12: =F12-G12 -> 67320 | I12: Emenda DASG nº 023/2025 — 20% do total dupla
B13: Secretário | C13: 10000 | D13: =C13*0.065 -> 650 | E13: =C13-D13 -> 9350 | F13: 15000 | G13: =F13*0.065 -> 975 | H13: =F13-G13 -> 14025 | I13: Licenciado ou superior
B16: B. TABELA DE CHAVES VLOOKUP (Usada automaticamente em LANÇAMENTOS — não editar)
B17: Chave VLOOKUP (Função|Tipo) | C17: Função | D17: Tipo | E17: Valor Bruto (Kz) | F17: IRT 6,5% | G17: Líquido (Kz) | H17: Nota
B18: Presidente de Júri|Individual | C18: Presidente de Júri | D18: Individual | E18: 20000 | F18: =E18*0.065 -> 1300 | G18: =E18-F18 -> 18700
B19: Presidente de Júri|Dupla | C19: Presidente de Júri | D19: Dupla | E19: 27500 | F19: =E19*0.065 -> 1787.5 | G19: =E19-F19 -> 25712.5
B20: 1º Vogal Arguente|Individual | C20: 1º Vogal Arguente | D20: Individual | E20: 20000 | F20: =E20*0.065 -> 1300 | G20: =E20-F20 -> 18700
B21: 1º Vogal Arguente|Dupla | C21: 1º Vogal Arguente | D21: Dupla | E21: 27500 | F21: =E21*0.065 -> 1787.5 | G21: =E21-F21 -> 25712.5
B22: 2º Vogal Tutor/Orientador|Individual | C22: 2º Vogal Tutor/Orientador | D22: Individual | E22: 80000 | F22: =E22*0.065 -> 5200 | G22: =E22-F22 -> 74800
B23: 2º Vogal Tutor/Orientador|Dupla | C23: 2º Vogal Tutor/Orientador | D23: Dupla | E23: 104000 | F23: =E23*0.065 -> 6760 | G23: =E23-F23 -> 97240
B24: Co-tutor|Individual | C24: Co-tutor | D24: Individual | E24: 40000 | F24: =E24*0.065 -> 2600 | G24: =E24-F24 -> 37400
B25: Co-tutor|Dupla | C25: Co-tutor | D25: Dupla | E25: 72000 | F25: =E25*0.065 -> 4680 | G25: =E25-F25 -> 67320
B26: Secretário|Individual | C26: Secretário | D26: Individual | E26: 10000 | F26: =E26*0.065 -> 650 | G26: =E26-F26 -> 9350
B27: Secretário|Dupla | C27: Secretário | D27: Dupla | E27: 15000 | F27: =E27*0.065 -> 975 | G27: =E27-F27 -> 14025
B29: ⚠ NOTA FISCAL: O IRT de 6,5% NÃO é calculado por sessão — incide sobre o TOTAL MENSAL por docente (ver folha RESUMO_IRT) | C.I.R.T. Art.º 67

Sheet 👥 MEMBROS_JÚRI
B2: REPÚBLICA DE ANGOLA — INSTITUTO SUPERIOR POLITÉCNICO DO LIBOLO (ISPTLO)
B3: REGISTO DE MEMBROS DE JÚRI — HIERARQUIA CIENTÍFICA ISPTLO
B4: Fonte: Normas de Hierarquização Científica do ISPTLO | D.P. nº 191/18 (ECDES) | Actualizado: 01/05/2026
B6: # | C6: Nome Completo | D6: Título Académico | E6: Categoria (ECDES) | F6: Departamento / Curso | G6: Funções Permitidas (por hierarquia) | H6: N.º Funcionário | I6: IBAN / Conta Bancária | J6: Contacto / E-mail
B7: 1 | C7: Manuel Octávio Isaac Spínola | D7: PhD | E7: Professor Associado | F7: Todas as áreas | G7: Presidente de Júri — APENAS Agronomia (máx. 1-2/sem.) | Cargo: Presidente do ISPTLO
B8: 2 | C8: Ideleichy Lombillo Rivero | D8: PhD | E8: Professora Catedrática | F8: Todas as áreas | G8: Presidente de Júri (todas áreas) | 1º Vogal em júris com PhD | 2º Vogal Tutora
B9: 3 | C9: Elizabeth González | D9: MSc/Doutoranda | E9: Professora Auxiliar | F9: [Departamento/Curso] | G9: Presidente (se PhD confirmado) | 1º Vogal Arguente | 2º Vogal Tutora | Co-tutora
B10: 4 | C10: Domingos Lunga | D10: Mestre | E10: Professor Auxiliar | F10: [Departamento/Curso] | G10: 1º Vogal Arguente | 2º Vogal Tutor | Co-tutor
B11: 5 | C11: José Fernando Manuel | D11: Mestre | E11: Professor Assistente | F11: [Departamento/Curso] | G11: 1º Vogal Arguente | 2º Vogal Tutor | Co-tutor
B12: 6 | C12: Walquiria Chissimo | D12: Mestre | E12: Professor Assistente | F12: [Departamento/Curso] | G12: 1º Vogal Arguente | 2º Vogal Tutora | Co-tutora
B13: 7 | C13: Félix Palau | D13: Mestre | E13: Professor Assistente | F13: [Departamento/Curso] | G13: 1º Vogal Arguente | 2º Vogal Tutor | Co-tutor
B14: 8 | C14: Marilda Augusto | D14: Licenciada | E14: Prof. Assistente Estagiária | F14: [Departamento/Curso] | G14: Secretária | Co-tutora (por despacho específico)
B15: 9 | C15: José Monteiro | D15: Licenciado | E15: Professor Assistente | F15: [Departamento/Curso] | G15: Secretário | Co-tutor (por despacho específico)
B16: 10 | C16: Domingos Ngando | D16: Licenciado | E16: Professor Assistente | F16: [Departamento/Curso] | G16: Secretário | Co-tutor (por despacho específico)
B19: LEGENDA DE HIERARQUIA (Normas ISPTLO) | Azul=PhD | Verde=Mestre/MSc | Cinzento=Licenciado
B20: 🔵 PhD — Nível 1 | Pode presidir júris
B21: 🟢 Mestre/MSc — Nível 2 | Arguente, Tutor, Co-tutor
B22: ⚪ Licenciado — Nível 3 | Secretário, Co-tutor por despacho

Sheet 📝 REGISTO_JÚRIS
B2: REPÚBLICA DE ANGOLA — INSTITUTO SUPERIOR POLITÉCNICO DO LIBOLO (ISPTLO)
B3: REGISTO DE BANCAS DE JÚRI — DATA ENTRY OPERACIONAL
B4: Campos em AZUL (🔵) = input manual | Listas suspensas (▼) = selecção obrigatória | Valores calculados automaticamente via VLOOKUP
B5: Nº | C5: Nº Despacho Nomeação | D5: Data Despacho | E5: Acto ▼ (Pré-Def./Def.) | F5: Estudante(s) — Nome(s) | G5: Título do TFC | H5: Curso / Dept. ▼ | I5: Tipo ▼ (Ind./Dupla) | J5: Data Pré-Defesa | K5: Data Defesa | L5: Mês/Ano Ref. (auto) | M5: Presidente ▼ (PhD) | N5: 1º Vogal ▼ (MSc+) | O5: 2º Vogal Tutor ▼ | P5: Co-tutor ▼ (se design.) | Q5: Secretário ▼ (Lic.) | R5: Resultado ▼ | S5: Observações
B6: 1 | C6: DESP-TFC-001/2026 | D6: 01/02/2026 | E6: Defesa | F6: António Sebastião | G6: Gestão da Qualidade no Ensino Superior em Angola | H6: Contabilidade e Gestão / CSH | I6: Individual | J6: 10/02/2026 | K6: 15/02/2026 | L6: =IF(K6="","",MID("JanFevMarAbrMaiJunJulAgoSetOutNovDez",VALUE(MID(K6,4,2))*3-2,3)&"/"&RIGHT(K6,4)) -> Fev/2026 | M6: Ideleichy Lombillo Rivero | N6: Walquiria Chissimo | O6: José Fernando Manuel | P6: — | Q6: Domingos Ngando | R6: 14
B7: 2 | C7: DESP-TFC-002/2026 | D7: 05/02/2026 | E7: Defesa | F7: Maria da Conceição / Pedro Lopes | G7: Impacto da Digitalização na Gestão Pública | H7: Contabilidade e Gestão / CSH | I7: Dupla | J7: 12/02/2026 | K7: 18/02/2026 | L7: =IF(K7="","",MID("JanFevMarAbrMaiJunJulAgoSetOutNovDez",VALUE(MID(K7,4,2))*3-2,3)&"/"&RIGHT(K7,4)) -> Fev/2026 | M7: Ideleichy Lombillo Rivero | N7: Domingos Lunga | O7: Félix Palau | P7: Eng. Valdim Seferino | Q7: José Monteiro | R7: 13
B8: 3 | C8: DESP-TFC-003/2026 | D8: 10/03/2026 | E8: Defesa | F8: Elisabete Nzola | G8: Métodos Pedagógicos no Ensino Rural em Angola | H8: Ensino Primário / CSH | I8: Individual | J8: 20/03/2026 | K8: 25/03/2026 | L8: =IF(K8="","",MID("JanFevMarAbrMaiJunJulAgoSetOutNovDez",VALUE(MID(K8,4,2))*3-2,3)&"/"&RIGHT(K8,4)) -> Mar/2026 | M8: Manuel Octávio Isaac Spínola | N8: Elizabeth González | O8: Walquiria Chissimo | P8: — | Q8: Marilda Augusto | R8: 15
L9: =IF(K9="","",MID("JanFevMarAbrMaiJunJulAgoSetOutNovDez",VALUE(MID(K9,4,2))*3-2,3)&"/"&RIGHT(K9,4))
L10: =IF(K10="","",MID("JanFevMarAbrMaiJunJulAgoSetOutNovDez",VALUE(MID(K10,4,2))*3-2,3)&"/"&RIGHT(K10,4))
L11: =IF(K11="","",MID("JanFevMarAbrMaiJunJulAgoSetOutNovDez",VALUE(MID(K11,4,2))*3-2,3)&"/"&RIGHT(K11,4))
L12: =IF(K12="","",MID("JanFevMarAbrMaiJunJulAgoSetOutNovDez",VALUE(MID(K12,4,2))*3-2,3)&"/"&RIGHT(K12,4))
L13: =IF(K13="","",MID("JanFevMarAbrMaiJunJulAgoSetOutNovDez",VALUE(MID(K13,4,2))*3-2,3)&"/"&RIGHT(K13,4))
L14: =IF(K14="","",MID("JanFevMarAbrMaiJunJulAgoSetOutNovDez",VALUE(MID(K14,4,2))*3-2,3)&"/"&RIGHT(K14,4))
L15: =IF(K15="","",MID("JanFevMarAbrMaiJunJulAgoSetOutNovDez",VALUE(MID(K15,4,2))*3-2,3)&"/"&RIGHT(K15,4))
L16: =IF(K16="","",MID("JanFevMarAbrMaiJunJulAgoSetOutNovDez",VALUE(MID(K16,4,2))*3-2,3)&"/"&RIGHT(K16,4))
L17: =IF(K17="","",MID("JanFevMarAbrMaiJunJulAgoSetOutNovDez",VALUE(MID(K17,4,2))*3-2,3)&"/"&RIGHT(K17,4))
L18: =IF(K18="","",MID("JanFevMarAbrMaiJunJulAgoSetOutNovDez",VALUE(MID(K18,4,2))*3-2,3)&"/"&RIGHT(K18,4))
L19: =IF(K19="","",MID("JanFevMarAbrMaiJunJulAgoSetOutNovDez",VALUE(MID(K19,4,2))*3-2,3)&"/"&RIGHT(K19,4))
L20: =IF(K20="","",MID("JanFevMarAbrMaiJunJulAgoSetOutNovDez",VALUE(MID(K20,4,2))*3-2,3)&"/"&RIGHT(K20,4))
... L50: =IF(K50="","",MID("JanFevMarAbrMaiJunJulAgoSetOutNovDez",VALUE(MID(K50,4,2))*3-2,3)&"/"&RIGHT(K50,4))

Sheet 💰 LANÇAMENTOS
B2: REPÚBLICA DE ANGOLA — INSTITUTO SUPERIOR POLITÉCNICO DO LIBOLO (ISPTLO)
B3: LANÇAMENTOS — DETALHE POR SESSÃO (Livro de Razão) | IRT NÃO calculado aqui
B4: ⚠ Esta folha regista APENAS o valor bruto por participação. A retenção de IRT (6,5%) é calculada sobre o TOTAL MENSAL na folha RESUMO_IRT.
B5: Nº | C5: Nº Despacho (de REGISTO) | D5: Nome do Docente ▼ | E5: Categoria / Nível | F5: Função ▼ | G5: Tipo ▼ (Ind./Dupla) | H5: Data Acto | I5: Mês/Ano (auto) | J5: Valor Bruto Sessão (Kz)
B6: 1 | C6: DESP-TFC-001/2026 | D6: Ideleichy Lombillo Rivero | E6: PhD | F6: Presidente de Júri | G6: Individual | H6: 15/02/2026 | I6: =IF(H6="","",MID("JanFevMarAbrMaiJunJulAgoSetOutNovDez",VALUE(MID(H6,4,2))*3-2,3)&"/"&RIGHT(H6,4)) -> Fev/2026 | J6: 20000
B7: 2 | C7: DESP-TFC-001/2026 | D7: Walquiria Chissimo | E7: MSc | F7: 1º Vogal Arguente | G7: Individual | H7: 15/02/2026 | I7: =IF(H7="","",MID("JanFevMarAbrMaiJunJulAgoSetOutNovDez",VALUE(MID(H7,4,2))*3-2,3)&"/"&RIGHT(H7,4)) -> Fev/2026 | J7: 20000
B8: 3 | C8: DESP-TFC-001/2026 | D8: José Fernando Manuel | E8: Mestre | F8: 2º Vogal Tutor/Orientador | G8: Individual | H8: 15/02/2026 | I8: =IF(H8="","",MID("JanFevMarAbrMaiJunJulAgoSetOutNovDez",VALUE(MID(H8,4,2))*3-2,3)&"/"&RIGHT(H8,4)) -> Fev/2026 | J8: 80000
B9: 4 | C9: DESP-TFC-001/2026 | D9: Domingos Ngando | E9: Lic | F9: Secretário | G9: Individual | H9: 15/02/2026 | I9: =IF(H9="","",MID("JanFevMarAbrMaiJunJulAgoSetOutNovDez",VALUE(MID(H9,4,2))*3-2,3)&"/"&RIGHT(H9,4)) -> Fev/2026 | J9: 10000
B10: 5 | C10: DESP-TFC-002/2026 | D10: Ideleichy Lombillo Rivero | E10: PhD | F10: Presidente de Júri | G10: Dupla | H10: 18/02/2026 | I10: =IF(H10="","",MID("JanFevMarAbrMaiJunJulAgoSetOutNovDez",VALUE(MID(H10,4,2))*3-2,3)&"/"&RIGHT(H10,4)) -> Fev/2026 | J10: 27500
B11: 6 | C11: DESP-TFC-002/2026 | D11: Domingos Lunga | E11: MSc | F11: 1º Vogal Arguente | G11: Dupla | H11: 18/02/2026 | I11: =IF(H11="","",MID("JanFevMarAbrMaiJunJulAgoSetOutNovDez",VALUE(MID(H11,4,2))*3-2,3)&"/"&RIGHT(H11,4)) -> Fev/2026 | J11: 27500
B12: 7 | C12: DESP-TFC-002/2026 | D12: Félix Palau | E12: Mestre | F12: 2º Vogal Tutor/Orientador | G12: Dupla | H12: 18/02/2026 | I12: =IF(H12="","",MID("JanFevMarAbrMaiJunJulAgoSetOutNovDez",VALUE(MID(H12,4,2))*3-2,3)&"/"&RIGHT(H12,4)) -> Fev/2026 | J12: 104000
B13: 8 | C13: DESP-TFC-002/2026 | D13: José Monteiro | E13: Lic | F13: Secretário | G13: Dupla | H13: 18/02/2026 | I13: =IF(H13="","",MID("JanFevMarAbrMaiJunJulAgoSetOutNovDez",VALUE(MID(H13,4,2))*3-2,3)&"/"&RIGHT(H13,4)) -> Fev/2026 | J13: 15000
B14: 9 | C14: DESP-TFC-003/2026 | D14: Manuel Octávio Isaac Spínola | E14: PhD | F14: Presidente de Júri | G14: Individual | H14: 25/03/2026 | I14: =IF(H14="","",MID("JanFevMarAbrMaiJunJulAgoSetOutNovDez",VALUE(MID(H14,4,2))*3-2,3)&"/"&RIGHT(H14,4)) -> Mar/2026 | J14: 20000
B15: 10 | C15: DESP-TFC-003/2026 | D15: Elizabeth González | E15: MSc | F15: 1º Vogal Arguente | G15: Individual | H15: 25/03/2026 | I15: =IF(H15="","",MID("JanFevMarAbrMaiJunJulAgoSetOutNovDez",VALUE(MID(H15,4,2))*3-2,3)&"/"&RIGHT(H15,4)) -> Mar/2026 | J15: 20000
B16: 11 | C16: DESP-TFC-003/2026 | D16: Walquiria Chissimo | E16: MSc | F16: 2º Vogal Tutor/Orientador | G16: Individual | H16: 25/03/2026 | I16: =IF(H16="","",MID("JanFevMarAbrMaiJunJulAgoSetOutNovDez",VALUE(MID(H16,4,2))*3-2,3)&"/"&RIGHT(H16,4)) -> Mar/2026 | J16: 80000
B17: 12 | C17: DESP-TFC-003/2026 | D17: Marilda Augusto | E17: Lic | F17: Secretário | G17: Individual | H17: 25/03/2026 | I17: =IF(H17="","",MID("JanFevMarAbrMaiJunJulAgoSetOutNovDez",VALUE(MID(H17,4,2))*3-2,3)&"/"&RIGHT(H17,4)) -> Mar/2026 | J17: 10000
I18: =IF(H18="","",MID("JanFevMarAbrMaiJunJulAgoSetOutNovDez",VALUE(MID(H18,4,2))*3-2,3)&"/"&RIGHT(H18,4)) | J18: =IFERROR(VLOOKUP(F18&"|"&G18,'📘 TABELA_SUBSÍDIOS'!$B$18:$E$27,4,0),"")
I19: =IF(H19="","",MID("JanFevMarAbrMaiJunJulAgoSetOutNovDez",VALUE(MID(H19,4,2))*3-2,3)&"/"&RIGHT(H19,4)) | J19: =IFERROR(VLOOKUP(F19&"|"&G19,'📘 TABELA_SUBSÍDIOS'!$B$18:$E$27,4,0),"")
I20: =IF(H20="","",MID("JanFevMarAbrMaiJunJulAgoSetOutNovDez",VALUE(MID(H20,4,2))*3-2,3)&"/"&RIGHT(H20,4)) | J20: =IFERROR(VLOOKUP(F20&"|"&G20,'📘 TABELA_SUBSÍDIOS'!$B$18:$E$27,4,0),"")
I21: =IF(H21="","",MID("JanFevMarAbrMaiJunJulAgoSetOutNovDez",VALUE(MID(H21,4,2))*3-2,3)&"/"&RIGHT(H21,4)) | J21: =IFERROR(VLOOKUP(F21&"|"&G21,'📘 TABELA_SUBSÍDIOS'!$B$18:$E$27,4,0),"")
I22: =IF(H22="","",MID("JanFevMarAbrMaiJunJulAgoSetOutNovDez",VALUE(MID(H22,4,2))*3-2,3)&"/"&RIGHT(H22,4)) | J22: =IFERROR(VLOOKUP(F22&"|"&G22,'📘 TABELA_SUBSÍDIOS'!$B$18:$E$27,4,0),"")
I23: =IF(H23="","",MID("JanFevMarAbrMaiJunJulAgoSetOutNovDez",VALUE(MID(H23,4,2))*3-2,3)&"/"&RIGHT(H23,4)) | J23: =IFERROR(VLOOKUP(F23&"|"&G23,'📘 TABELA_SUBSÍDIOS'!$B$18:$E$27,4,0),"")
I24: =IF(H24="","",MID("JanFevMarAbrMaiJunJulAgoSetOutNovDez",VALUE(MID(H24,4,2))*3-2,3)&"/"&RIGHT(H24,4)) | J24: =IFERROR(VLOOKUP(F24&"|"&G24,'📘 TABELA_SUBSÍDIOS'!$B$18:$E$27,4,0),"")
I25: =IF(H25="","",MID("JanFevMarAbrMaiJunJulAgoSetOutNovDez",VALUE(MID(H25,4,2))*3-2,3)&"/"&RIGHT(H25,4)) | J25: =IFERROR(VLOOKUP(F25&"|"&G25,'📘 TABELA_SUBSÍDIOS'!$B$18:$E$27,4,0),"")
I26: =IF(H26="","",MID("JanFevMarAbrMaiJunJulAgoSetOutNovDez",VALUE(MID(H26,4,2))*3-2,3)&"/"&RIGHT(H26,4)) | J26: =IFERROR(VLOOKUP(F26&"|"&G26,'📘 TABELA_SUBSÍDIOS'!$B$18:$E$27,4,0),"")
I27: =IF(H27="","",MID("JanFevMarAbrMaiJunJulAgoSetOutNovDez",VALUE(MID(H27,4,2))*3-2,3)&"/"&RIGHT(H27,4)) | J27: =IFERROR(VLOOKUP(F27&"|"&G27,'📘 TABELA_SUBSÍDIOS'!$B$18:$E$27,4,0),"")
I28: =IF(H28="","",MID("JanFevMarAbrMaiJunJulAgoSetOutNovDez",VALUE(MID(H28,4,2))*3-2,3)&"/"&RIGHT(H28,4)) | J28: =IFERROR(VLOOKUP(F28&"|"&G28,'📘 TABELA_SUBSÍDIOS'!$B$18:$E$27,4,0),"")
I29: =IF(H29="","",MID("JanFevMarAbrMaiJunJulAgoSetOutNovDez",VALUE(MID(H29,4,2))*3-2,3)&"/"&RIGHT(H29,4)) | J29: =IFERROR(VLOOKUP(F29&"|"&G29,'📘 TABELA_SUBSÍDIOS'!$B$18:$E$27,4,0),"")
... I59: =IF(H59="","",MID("JanFevMarAbrMaiJunJulAgoSetOutNovDez",VALUE(MID(H59,4,2))*3-2,3)&"/"&RIGHT(H59,4)) | J59: =IFERROR(VLOOKUP(F59&"|"&G59,'📘 TABELA_SUBSÍDIOS'!$B$18:$E$27,4,0),"")
B60: TOTAL BRUTO LANÇAMENTOS (sem IRT) | J60: =SUMIF(J6:J59,">0") -> 434000

Sheet 🧾 RESUMO_IRT
B2: REPÚBLICA DE ANGOLA — INSTITUTO SUPERIOR POLITÉCNICO DO LIBOLO (ISPTLO)
B3: 🧾 RESUMO IRT — CÁLCULO DE RETENÇÃO MENSAL POR DOCENTE
B5: ⭐ REGRA FISCAL IMPERATIVA: O IRT de 6,5% é calculado sobre o TOTAL BRUTO MENSAL por docente (soma de TODAS as participações no mês), NÃO por sessão individual — C.I.R.T. Lei nº 19/14 Art.º 67
B6: EXEMPLO: Ideleichy Lombillo — Mar/2026: 20.000 (presidente indiv.) + 27.500 (presidente dupla) + 104.000 (tutora dupla) = TOTAL 151.500 Kz → IRT = 151.500 × 6,5% = 9.847,50 Kz → LÍQUIDO = 141.652,50 Kz
B7: Nº | C7: Nome do Docente | D7: Mês/Ano Referência | E7: Total Bruto Mensal (Kz) | F7: IRT 6,5% (sobre total) | G7: Valor Líquido a Pagar (Kz) | H7: Valor Pago (Kz) | I7: Saldo em Atraso (Kz) | J7: Data de Pagamento | K7: Canal de Pagamento | L7: Comprovativo (Ref./Nº) | M7: Estado
B8: 1 | C8: Ideleichy Lombillo Rivero | D8: Fev/2026 | E8: =SUMIFS('💰 LANÇAMENTOS'!$J:$J,'💰 LANÇAMENTOS'!$D:$D,C8,'💰 LANÇAMENTOS'!$I:$I,D8) -> 47500 | F8: =IF(E8=0,0,E8*0.065) -> 3087.5 | G8: =IF(E8=0,"",E8-F8) -> 44412.5 | I8: =IF(G8="","",G8-IF(H8="",0,H8)) -> 44412.5 | M8: =IF(E8=0,"—",IF(H8="","EM ATRASO",IF(H8>=G8,"PAGO",IF(H8>0,"PARCIAL","EM ATRASO")))) -> EM ATRASO
B9: 2 | C9: Walquiria Chissimo | D9: Fev/2026 | E9: =SUMIFS('💰 LANÇAMENTOS'!$J:$J,'💰 LANÇAMENTOS'!$D:$D,C9,'💰 LANÇAMENTOS'!$I:$I,D9) -> 20000 | F9: =IF(E9=0,0,E9*0.065) -> 1300 | G9: =IF(E9=0,"",E9-F9) -> 18700 | I9: =IF(G9="","",G9-IF(H9="",0,H9)) -> 18700 | M9: =IF(E9=0,"—",IF(H9="","EM ATRASO",IF(H9>=G9,"PAGO",IF(H9>0,"PARCIAL","EM ATRASO")))) -> EM ATRASO
B10: 3 | C10: José Fernando Manuel | D10: Fev/2026 | E10: =SUMIFS('💰 LANÇAMENTOS'!$J:$J,'💰 LANÇAMENTOS'!$D:$D,C10,'💰 LANÇAMENTOS'!$I:$I,D10) -> 80000 | F10: =IF(E10=0,0,E10*0.065) -> 5200 | G10: =IF(E10=0,"",E10-F10) -> 74800 | I10: =IF(G10="","",G10-IF(H10="",0,H10)) -> 74800 | M10: =IF(E10=0,"—",IF(H10="","EM ATRASO",IF(H10>=G10,"PAGO",IF(H10>0,"PARCIAL","EM ATRASO")))) -> EM ATRASO
B11: 4 | C11: Domingos Ngando | D11: Fev/2026 | E11: =SUMIFS('💰 LANÇAMENTOS'!$J:$J,'💰 LANÇAMENTOS'!$D:$D,C11,'💰 LANÇAMENTOS'!$I:$I,D11) -> 10000 | F11: =IF(E11=0,0,E11*0.065) -> 650 | G11: =IF(E11=0,"",E11-F11) -> 9350 | I11: =IF(G11="","",G11-IF(H11="",0,H11)) -> 9350 | M11: =IF(E11=0,"—",IF(H11="","EM ATRASO",IF(H11>=G11,"PAGO",IF(H11>0,"PARCIAL","EM ATRASO")))) -> EM ATRASO
B12: 5 | C12: Domingos Lunga | D12: Fev/2026 | E12: =SUMIFS('💰 LANÇAMENTOS'!$J:$J,'💰 LANÇAMENTOS'!$D:$D,C12,'💰 LANÇAMENTOS'!$I:$I,D12) -> 27500 | F12: =IF(E12=0,0,E12*0.065) -> 1787.5 | G12: =IF(E12=0,"",E12-F12) -> 25712.5 | I12: =IF(G12="","",G12-IF(H12="",0,H12)) -> 25712.5 | M12: =IF(E12=0,"—",IF(H12="","EM ATRASO",IF(H12>=G12,"PAGO",IF(H12>0,"PARCIAL","EM ATRASO")))) -> EM ATRASO
B13: 6 | C13: Félix Palau | D13: Fev/2026 | E13: =SUMIFS('💰 LANÇAMENTOS'!$J:$J,'💰 LANÇAMENTOS'!$D:$D,C13,'💰 LANÇAMENTOS'!$I:$I,D13) -> 104000 | F13: =IF(E13=0,0,E13*0.065) -> 6760 | G13: =IF(E13=0,"",E13-F13) -> 97240 | I13: =IF(G13="","",G13-IF(H13="",0,H13)) -> 97240 | M13: =IF(E13=0,"—",IF(H13="","EM ATRASO",IF(H13>=G13,"PAGO",IF(H13>0,"PARCIAL","EM ATRASO")))) -> EM ATRASO
B14: 7 | C14: José Monteiro | D14: Fev/2026 | E14: =SUMIFS('💰 LANÇAMENTOS'!$J:$J,'💰 LANÇAMENTOS'!$D:$D,C14,'💰 LANÇAMENTOS'!$I:$I,D14) -> 15000 | F14: =IF(E14=0,0,E14*0.065) -> 975 | G14: =IF(E14=0,"",E14-F14) -> 14025 | I14: =IF(G14="","",G14-IF(H14="",0,H14)) -> 14025 | M14: =IF(E14=0,"—",IF(H14="","EM ATRASO",IF(H14>=G14,"PAGO",IF(H14>0,"PARCIAL","EM ATRASO")))) -> EM ATRASO
B15: 8 | C15: Manuel Octávio Isaac Spínola | D15: Mar/2026 | E15: =SUMIFS('💰 LANÇAMENTOS'!$J:$J,'💰 LANÇAMENTOS'!$D:$D,C15,'💰 LANÇAMENTOS'!$I:$I,D15) -> 20000 | F15: =IF(E15=0,0,E15*0.065) -> 1300 | G15: =IF(E15=0,"",E15-F15) -> 18700 | I15: =IF(G15="","",G15-IF(H15="",0,H15)) -> 18700 | M15: =IF(E15=0,"—",IF(H15="","EM ATRASO",IF(H15>=G15,"PAGO",IF(H15>0,"PARCIAL","EM ATRASO")))) -> EM ATRASO
B16: 9 | C16: Elizabeth González | D16: Mar/2026 | E16: =SUMIFS('💰 LANÇAMENTOS'!$J:$J,'💰 LANÇAMENTOS'!$D:$D,C16,'💰 LANÇAMENTOS'!$I:$I,D16) -> 20000 | F16: =IF(E16=0,0,E16*0.065) -> 1300 | G16: =IF(E16=0,"",E16-F16) -> 18700 | I16: =IF(G16="","",G16-IF(H16="",0,H16)) -> 18700 | M16: =IF(E16=0,"—",IF(H16="","EM ATRASO",IF(H16>=G16,"PAGO",IF(H16>0,"PARCIAL","EM ATRASO")))) -> EM ATRASO
B17: 10 | C17: Walquiria Chissimo | D17: Mar/2026 | E17: =SUMIFS('💰 LANÇAMENTOS'!$J:$J,'💰 LANÇAMENTOS'!$D:$D,C17,'💰 LANÇAMENTOS'!$I:$I,D17) -> 80000 | F17: =IF(E17=0,0,E17*0.065) -> 5200 | G17: =IF(E17=0,"",E17-F17) -> 74800 | I17: =IF(G17="","",G17-IF(H17="",0,H17)) -> 74800 | M17: =IF(E17=0,"—",IF(H17="","EM ATRASO",IF(H17>=G17,"PAGO",IF(H17>0,"PARCIAL","EM ATRASO")))) -> EM ATRASO
B18: 11 | C18: Marilda Augusto | D18: Mar/2026 | E18: =SUMIFS('💰 LANÇAMENTOS'!$J:$J,'💰 LANÇAMENTOS'!$D:$D,C18,'💰 LANÇAMENTOS'!$I:$I,D18) -> 10000 | F18: =IF(E18=0,0,E18*0.065) -> 650 | G18: =IF(E18=0,"",E18-F18) -> 9350 | I18: =IF(G18="","",G18-IF(H18="",0,H18)) -> 9350 | M18: =IF(E18=0,"—",IF(H18="","EM ATRASO",IF(H18>=G18,"PAGO",IF(H18>0,"PARCIAL","EM ATRASO")))) -> EM ATRASO
E19: =SUMIFS('💰 LANÇAMENTOS'!$J:$J,'💰 LANÇAMENTOS'!$D:$D,C19,'💰 LANÇAMENTOS'!$I:$I,D19) -> 0 | F19: =IF(E19=0,0,E19*0.065) -> 0 | G19: =IF(E19=0,"",E19-F19) | I19: =IF(G19="","",G19-IF(H19="",0,H19)) | M19: =IF(E19=0,"—",IF(H19="","EM ATRASO",IF(H19>=G19,"PAGO",IF(H19>0,"PARCIAL","EM ATRASO")))) -> —
E20: =SUMIFS('💰 LANÇAMENTOS'!$J:$J,'💰 LANÇAMENTOS'!$D:$D,C20,'💰 LANÇAMENTOS'!$I:$I,D20) -> 0 | F20: =IF(E20=0,0,E20*0.065) -> 0 | G20: =IF(E20=0,"",E20-F20) | I20: =IF(G20="","",G20-IF(H20="",0,H20)) | M20: =IF(E20=0,"—",IF(H20="","EM ATRASO",IF(H20>=G20,"PAGO",IF(H20>0,"PARCIAL","EM ATRASO")))) -> —
E21: =SUMIFS('💰 LANÇAMENTOS'!$J:$J,'💰 LANÇAMENTOS'!$D:$D,C21,'💰 LANÇAMENTOS'!$I:$I,D21) -> 0 | F21: =IF(E21=0,0,E21*0.065) -> 0 | G21: =IF(E21=0,"",E21-F21) | I21: =IF(G21="","",G21-IF(H21="",0,H21)) | M21: =IF(E21=0,"—",IF(H21="","EM ATRASO",IF(H21>=G21,"PAGO",IF(H21>0,"PARCIAL","EM ATRASO")))) -> —
E22: =SUMIFS('💰 LANÇAMENTOS'!$J:$J,'💰 LANÇAMENTOS'!$D:$D,C22,'💰 LANÇAMENTOS'!$I:$I,D22) -> 0 | F22: =IF(E22=0,0,E22*0.065) -> 0 | G22: =IF(E22=0,"",E22-F22) | I22: =IF(G22="","",G22-IF(H22="",0,H22)) | M22: =IF(E22=0,"—",IF(H22="","EM ATRASO",IF(H22>=G22,"PAGO",IF(H22>0,"PARCIAL","EM ATRASO")))) -> —
E23: =SUMIFS('💰 LANÇAMENTOS'!$J:$J,'💰 LANÇAMENTOS'!$D:$D,C23,'💰 LANÇAMENTOS'!$I:$I,D23) -> 0 | F23: =IF(E23=0,0,E23*0.065) -> 0 | G23: =IF(E23=0,"",E23-F23) | I23: =IF(G23="","",G23-IF(H23="",0,H23)) | M23: =IF(E23=0,"—",IF(H23="","EM ATRASO",IF(H23>=G23,"PAGO",IF(H23>0,"PARCIAL","EM ATRASO")))) -> —
E24: =SUMIFS('💰 LANÇAMENTOS'!$J:$J,'💰 LANÇAMENTOS'!$D:$D,C24,'💰 LANÇAMENTOS'!$I:$I,D24) -> 0 | F24: =IF(E24=0,0,E24*0.065) -> 0 | G24: =IF(E24=0,"",E24-F24) | I24: =IF(G24="","",G24-IF(H24="",0,H24)) | M24: =IF(E24=0,"—",IF(H24="","EM ATRASO",IF(H24>=G24,"PAGO",IF(H24>0,"PARCIAL","EM ATRASO")))) -> —
E25: =SUMIFS('💰 LANÇAMENTOS'!$J:$J,'💰 LANÇAMENTOS'!$D:$D,C25,'💰 LANÇAMENTOS'!$I:$I,D25) -> 0 | F25: =IF(E25=0,0,E25*0.065) -> 0 | G25: =IF(E25=0,"",E25-F25) | I25: =IF(G25="","",G25-IF(H25="",0,H25)) | M25: =IF(E25=0,"—",IF(H25="","EM ATRASO",IF(H25>=G25,"PAGO",IF(H25>0,"PARCIAL","EM ATRASO")))) -> —
E26: =SUMIFS('💰 LANÇAMENTOS'!$J:$J,'💰 LANÇAMENTOS'!$D:$D,C26,'💰 LANÇAMENTOS'!$I:$I,D26) -> 0 | F26: =IF(E26=0,0,E26*0.065) -> 0 | G26: =IF(E26=0,"",E26-F26) | I26: =IF(G26="","",G26-IF(H26="",0,H26)) | M26: =IF(E26=0,"—",IF(H26="","EM ATRASO",IF(H26>=G26,"PAGO",IF(H26>0,"PARCIAL","EM ATRASO")))) -> —
E27: =SUMIFS('💰 LANÇAMENTOS'!$J:$J,'💰 LANÇAMENTOS'!$D:$D,C27,'💰 LANÇAMENTOS'!$I:$I,D27) -> 0 | F27: =IF(E27=0,0,E27*0.065) -> 0 | G27: =IF(E27=0,"",E27-F27) | I27: =IF(G27="","",G27-IF(H27="",0,H27)) | M27: =IF(E27=0,"—",IF(H27="","EM ATRASO",IF(H27>=G27,"PAGO",IF(H27>0,"PARCIAL","EM ATRASO")))) -> —
E28: =SUMIFS('💰 LANÇAMENTOS'!$J:$J,'💰 LANÇAMENTOS'!$D:$D,C28,'💰 LANÇAMENTOS'!$I:$I,D28) -> 0 | F28: =IF(E28=0,0,E28*0.065) -> 0 | G28: =IF(E28=0,"",E28-F28) | I28: =IF(G28="","",G28-IF(H28="",0,H28)) | M28: =IF(E28=0,"—",IF(H28="","EM ATRASO",IF(H28>=G28,"PAGO",IF(H28>0,"PARCIAL","EM ATRASO")))) -> —
E29: =SUMIFS('💰 LANÇAMENTOS'!$J:$J,'💰 LANÇAMENTOS'!$D:$D,C29,'💰 LANÇAMENTOS'!$I:$I,D29) -> 0 | F29: =IF(E29=0,0,E29*0.065) -> 0 | G29: =IF(E29=0,"",E29-F29) | I29: =IF(G29="","",G29-IF(H29="",0,H29)) | M29: =IF(E29=0,"—",IF(H29="","EM ATRASO",IF(H29>=G29,"PAGO",IF(H29>0,"PARCIAL","EM ATRASO")))) -> —
E30: =SUMIFS('💰 LANÇAMENTOS'!$J:$J,'💰 LANÇAMENTOS'!$D:$D,C30,'💰 LANÇAMENTOS'!$I:$I,D30) -> 0 | F30: =IF(E30=0,0,E30*0.065) -> 0 | G30: =IF(E30=0,"",E30-F30) | I30: =IF(G30="","",G30-IF(H30="",0,H30)) | M30: =IF(E30=0,"—",IF(H30="","EM ATRASO",IF(H30>=G30,"PAGO",IF(H30>0,"PARCIAL","EM ATRASO")))) -> —
... E45: =SUMIFS('💰 LANÇAMENTOS'!$J:$J,'💰 LANÇAMENTOS'!$D:$D,C45,'💰 LANÇAMENTOS'!$I:$I,D45) -> 0 | F45: =IF(E45=0,0,E45*0.065) -> 0 | G45: =IF(E45=0,"",E45-F45) | I45: =IF(G45="","",G45-IF(H45="",0,H45)) | M45: =IF(E45=0,"—",IF(H45="","EM ATRASO",IF(H45>=G45,"PAGO",IF(H45>0,"PARCIAL","EM ATRASO")))) -> —
B46: TOTAIS GERAIS (RESUMO IRT) | E46: =SUMIF(E8:E45,">0") -> 434000 | F46: =SUMIF(F8:F45,">0") -> 28210 | G46: =SUMIF(G8:G45,">0") -> 405790 | H46: =SUMIF(H8:H45,">0") -> 0 | I46: =SUMIF(I8:I45,">0") -> 405790

Sheet 📊 DASHBOARD
B2: REPÚBLICA DE ANGOLA — INSTITUTO SUPERIOR POLITÉCNICO DO LIBOLO (ISPTLO)
B3: Actualizado em: 01/05/2026 | Partilha mensal: Vice-Presidência Académica + Directores de Departamento (Acordo 1.3)
B5: TOTAL BRUTO (todos os lançamentos) | D5: TOTAL IRT Retido (a entregar AGT) | F5: TOTAL LÍQUIDO a Transferir
B6: ='🧾 RESUMO_IRT'!E46 -> 434000 | D6: ='🧾 RESUMO_IRT'!F46 -> 28210 | F6: ='🧾 RESUMO_IRT'!G46 -> 405790
B7: Soma de todos os valores brutos por sessão | D7: 6,5% sobre total mensal/docente → AGT | F7: Valor efectivo a pagar aos docentes
B9: ⚠ TOTAL IRT A ENTREGAR À AGT: O valor na célula D6 deve ser declarado e entregue à Administração Geral Tributária nos termos do C.I.R.T. (Lei nº 19/14). Prazo: até ao dia 20 do mês seguinte ao do pagamento.
B11: RESUMO POR ESTADO DE PAGAMENTO (baseado em RESUMO_IRT)
B12: Estado | C12: Nº Docentes | D12: Total Bruto (Kz) | E12: IRT (Kz) | F12: Líquido (Kz) | G12: % do Bruto Total
B13: PAGO | C13: =COUNTIF('🧾 RESUMO_IRT'!M8:M45,"PAGO") -> 0 | D13: =SUMPRODUCT(('🧾 RESUMO_IRT'!M8:M45="PAGO")*IF('🧾 RESUMO_IRT'!E8:E45="",0,'🧾 RESUMO_IRT'!E8:E45)) -> 0 | E13: =SUMPRODUCT(('🧾 RESUMO_IRT'!M8:M45="PAGO")*IF('🧾 RESUMO_IRT'!F8:F45="",0,'🧾 RESUMO_IRT'!F8:F45)) -> 0 | F13: =SUMPRODUCT(('🧾 RESUMO_IRT'!M8:M45="PAGO")*IF('🧾 RESUMO_IRT'!G8:G45="",0,'🧾 RESUMO_IRT'!G8:G45)) -> #VALUE! | G13: =IF('🧾 RESUMO_IRT'!E46=0,"—",D13/'🧾 RESUMO_IRT'!E46) -> 0
B14: EM ATRASO | C14: =COUNTIF('🧾 RESUMO_IRT'!M8:M45,"EM ATRASO") -> 11 | D14: =SUMPRODUCT(('🧾 RESUMO_IRT'!M8:M45="EM ATRASO")*IF('🧾 RESUMO_IRT'!E8:E45="",0,'🧾 RESUMO_IRT'!E8:E45)) -> 434000 | E14: =SUMPRODUCT(('🧾 RESUMO_IRT'!M8:M45="EM ATRASO")*IF('🧾 RESUMO_IRT'!F8:F45="",0,'🧾 RESUMO_IRT'!F8:F45)) -> 28210 | F14: =SUMPRODUCT(('🧾 RESUMO_IRT'!M8:M45="EM ATRASO")*IF('🧾 RESUMO_IRT'!G8:G45="",0,'🧾 RESUMO_IRT'!G8:G45)) -> #VALUE! | G14: =IF('🧾 RESUMO_IRT'!E46=0,"—",D14/'🧾 RESUMO_IRT'!E46) -> 1
B15: PARCIAL | C15: =COUNTIF('🧾 RESUMO_IRT'!M8:M45,"PARCIAL") -> 0 | D15: =SUMPRODUCT(('🧾 RESUMO_IRT'!M8:M45="PARCIAL")*IF('🧾 RESUMO_IRT'!E8:E45="",0,'🧾 RESUMO_IRT'!E8:E45)) -> 0 | E15: =SUMPRODUCT(('🧾 RESUMO_IRT'!M8:M45="PARCIAL")*IF('🧾 RESUMO_IRT'!F8:F45="",0,'🧾 RESUMO_IRT'!F8:F45)) -> 0 | F15: =SUMPRODUCT(('🧾 RESUMO_IRT'!M8:M45="PARCIAL")*IF('🧾 RESUMO_IRT'!G8:G45="",0,'🧾 RESUMO_IRT'!G8:G45)) -> #VALUE! | G15: =IF('🧾 RESUMO_IRT'!E46=0,"—",D15/'🧾 RESUMO_IRT'!E46) -> 0
B17: RESUMO MENSAL — BRUTO / IRT / LÍQUIDO / SALDO EM ATRASO
B18: Mês/Ano | C18: Nº Participações | D18: Bruto Total (Kz) | E18: IRT Total (Kz) | F18: Líquido Total (Kz) | G18: Saldo em Atraso (Kz)
B19: Fev/2026 | C19: =COUNTIF('🧾 RESUMO_IRT'!D8:D45,"Fev/2026") -> 7 | D19: =SUMIF('🧾 RESUMO_IRT'!D8:D45,"Fev/2026",'🧾 RESUMO_IRT'!E8:E45) -> 304000 | E19: =SUMIF('🧾 RESUMO_IRT'!D8:D45,"Fev/2026",'🧾 RESUMO_IRT'!F8:F45) -> 19760 | F19: =SUMIF('🧾 RESUMO_IRT'!D8:D45,"Fev/2026",'🧾 RESUMO_IRT'!G8:G45) -> 284240 | G19: =SUMIF('🧾 RESUMO_IRT'!D8:D45,"Fev/2026",'🧾 RESUMO_IRT'!I8:I45) -> 284240
B20: Mar/2026 | C20: =COUNTIF('🧾 RESUMO_IRT'!D8:D45,"Mar/2026") -> 4 | D20: =SUMIF('🧾 RESUMO_IRT'!D8:D45,"Mar/2026",'🧾 RESUMO_IRT'!E8:E45) -> 130000 | E20: =SUMIF('🧾 RESUMO_IRT'!D8:D45,"Mar/2026",'🧾 RESUMO_IRT'!F8:F45) -> 8450 | F20: =SUMIF('🧾 RESUMO_IRT'!D8:D45,"Mar/2026",'🧾 RESUMO_IRT'!G8:G45) -> 121550 | G20: =SUMIF('🧾 RESUMO_IRT'!D8:D45,"Mar/2026",'🧾 RESUMO_IRT'!I8:I45) -> 121550
B21: Abr/2026 | C21: =COUNTIF('🧾 RESUMO_IRT'!D8:D45,"Abr/2026") -> 0 | D21: =SUMIF('🧾 RESUMO_IRT'!D8:D45,"Abr/2026",'🧾 RESUMO_IRT'!E8:E45) -> 0 | E21: =SUMIF('🧾 RESUMO_IRT'!D8:D45,"Abr/2026",'🧾 RESUMO_IRT'!F8:F45) -> 0 | F21: =SUMIF('🧾 RESUMO_IRT'!D8:D45,"Abr/2026",'🧾 RESUMO_IRT'!G8:G45) -> 0 | G21: =SUMIF('🧾 RESUMO_IRT'!D8:D45,"Abr/2026",'🧾 RESUMO_IRT'!I8:I45) -> 0
B22: Mai/2026 | C22: =COUNTIF('🧾 RESUMO_IRT'!D8:D45,"Mai/2026") -> 0 | D22: =SUMIF('🧾 RESUMO_IRT'!D8:D45,"Mai/2026",'🧾 RESUMO_IRT'!E8:E45) -> 0 | E22: =SUMIF('🧾 RESUMO_IRT'!D8:D45,"Mai/2026",'🧾 RESUMO_IRT'!F8:F45) -> 0 | F22: =SUMIF('🧾 RESUMO_IRT'!D8:D45,"Mai/2026",'🧾 RESUMO_IRT'!G8:G45) -> 0 | G22: =SUMIF('🧾 RESUMO_IRT'!D8:D45,"Mai/2026",'🧾 RESUMO_IRT'!I8:I45) -> 0
B23: Jun/2026 | C23: =COUNTIF('🧾 RESUMO_IRT'!D8:D45,"Jun/2026") -> 0 | D23: =SUMIF('🧾 RESUMO_IRT'!D8:D45,"Jun/2026",'🧾 RESUMO_IRT'!E8:E45) -> 0 | E23: =SUMIF('🧾 RESUMO_IRT'!D8:D45,"Jun/2026",'🧾 RESUMO_IRT'!F8:F45) -> 0 | F23: =SUMIF('🧾 RESUMO_IRT'!D8:D45,"Jun/2026",'🧾 RESUMO_IRT'!G8:G45) -> 0 | G23: =SUMIF('🧾 RESUMO_IRT'!D8:D45,"Jun/2026",'🧾 RESUMO_IRT'!I8:I45) -> 0
B24: Jul/2026 | C24: =COUNTIF('🧾 RESUMO_IRT'!D8:D45,"Jul/2026") -> 0 | D24: =SUMIF('🧾 RESUMO_IRT'!D8:D45,"Jul/2026",'🧾 RESUMO_IRT'!E8:E45) -> 0 | E24: =SUMIF('🧾 RESUMO_IRT'!D8:D45,"Jul/2026",'🧾 RESUMO_IRT'!F8:F45) -> 0 | F24: =SUMIF('🧾 RESUMO_IRT'!D8:D45,"Jul/2026",'🧾 RESUMO_IRT'!G8:G45) -> 0 | G24: =SUMIF('🧾 RESUMO_IRT'!D8:D45,"Jul/2026",'🧾 RESUMO_IRT'!I8:I45) -> 0
B27: RESUMO POR DOCENTE — TOTAL BRUTO / IRT / LÍQUIDO / ESTADO
B28: Docente | C28: Meses Activos | D28: Total Bruto (Kz) | E28: Total IRT (Kz) | F28: Total Líquido (Kz) | G28: Estado Geral
B29: Manuel Octávio Isaac Spínola | C29: =COUNTIF('🧾 RESUMO_IRT'!C8:C45,"Manuel Octávio Isaac Spínola") -> 1 | D29: =SUMIF('🧾 RESUMO_IRT'!C8:C45,"Manuel Octávio Isaac Spínola",'🧾 RESUMO_IRT'!E8:E45) -> 20000 | E29: =SUMIF('🧾 RESUMO_IRT'!C8:C45,"Manuel Octávio Isaac Spínola",'🧾 RESUMO_IRT'!F8:F45) -> 1300 | F29: =SUMIF('🧾 RESUMO_IRT'!C8:C45,"Manuel Octávio Isaac Spínola",'🧾 RESUMO_IRT'!G8:G45) -> 18700 | G29: =IF(COUNTIF('🧾 RESUMO_IRT'!C8:C45,"Manuel Octávio Isaac Spínola")=0,"Sem registo",IF(SUMIF('🧾 RESUMO_IRT'!C8:C45,"Manuel Octávio Isaac Spínola",'🧾 RESUMO_IRT'!I8:I45)<=0,"PAGO",IF(SUMIF('🧾 RESUMO_IRT'!C8:C45,"Manuel Octávio Isaac Spínola",'🧾 RESUMO_IRT'!H8:H45)>0,"PARCIAL","EM ATRASO"))) -> EM ATRASO
B30: Ideleichy Lombillo Rivero | C30: =COUNTIF('🧾 RESUMO_IRT'!C8:C45,"Ideleichy Lombillo Rivero") -> 1 | D30: =SUMIF('🧾 RESUMO_IRT'!C8:C45,"Ideleichy Lombillo Rivero",'🧾 RESUMO_IRT'!E8:E45) -> 47500 | E30: =SUMIF('🧾 RESUMO_IRT'!C8:C45,"Ideleichy Lombillo Rivero",'🧾 RESUMO_IRT'!F8:F45) -> 3087.5 | F30: =SUMIF('🧾 RESUMO_IRT'!C8:C45,"Ideleichy Lombillo Rivero",'🧾 RESUMO_IRT'!G8:G45) -> 44412.5 | G30: =IF(COUNTIF('🧾 RESUMO_IRT'!C8:C45,"Ideleichy Lombillo Rivero")=0,"Sem registo",IF(SUMIF('🧾 RESUMO_IRT'!C8:C45,"Ideleichy Lombillo Rivero",'🧾 RESUMO_IRT'!I8:I45)<=0,"PAGO",IF(SUMIF('🧾 RESUMO_IRT'!C8:C45,"Ideleichy Lombillo Rivero",'🧾 RESUMO_IRT'!H8:H45)>0,"PARCIAL","EM ATRASO"))) -> EM ATRASO
B31: Elizabeth González | C31: =COUNTIF('🧾 RESUMO_IRT'!C8:C45,"Elizabeth González") -> 1 | D31: =SUMIF('🧾 RESUMO_IRT'!C8:C45,"Elizabeth González",'🧾 RESUMO_IRT'!E8:E45) -> 20000 | E31: =SUMIF('🧾 RESUMO_IRT'!C8:C45,"Elizabeth González",'🧾 RESUMO_IRT'!F8:F45) -> 1300 | F31: =SUMIF('🧾 RESUMO_IRT'!C8:C45,"Elizabeth González",'🧾 RESUMO_IRT'!G8:G45) -> 18700 | G31: =IF(COUNTIF('🧾 RESUMO_IRT'!C8:C45,"Elizabeth González")=0,"Sem registo",IF(SUMIF('🧾 RESUMO_IRT'!C8:C45,"Elizabeth González",'🧾 RESUMO_IRT'!I8:I45)<=0,"PAGO",IF(SUMIF('🧾 RESUMO_IRT'!C8:C45,"Elizabeth González",'🧾 RESUMO_IRT'!H8:H45)>0,"PARCIAL","EM ATRASO"))) -> EM ATRASO
B32: Domingos Lunga | C32: =COUNTIF('🧾 RESUMO_IRT'!C8:C45,"Domingos Lunga") -> 1 | D32: =SUMIF('🧾 RESUMO_IRT'!C8:C45,"Domingos Lunga",'🧾 RESUMO_IRT'!E8:E45) -> 27500 | E32: =SUMIF('🧾 RESUMO_IRT'!C8:C45,"Domingos Lunga",'🧾 RESUMO_IRT'!F8:F45) -> 1787.5 | F32: =SUMIF('🧾 RESUMO_IRT'!C8:C45,"Domingos Lunga",'🧾 RESUMO_IRT'!G8:G45) -> 25712.5 | G32: =IF(COUNTIF('🧾 RESUMO_IRT'!C8:C45,"Domingos Lunga")=0,"Sem registo",IF(SUMIF('🧾 RESUMO_IRT'!C8:C45,"Domingos Lunga",'🧾 RESUMO_IRT'!I8:I45)<=0,"PAGO",IF(SUMIF('🧾 RESUMO_IRT'!C8:C45,"Domingos Lunga",'🧾 RESUMO_IRT'!H8:H45)>0,"PARCIAL","EM ATRASO"))) -> EM ATRASO
B33: José Fernando Manuel | C33: =COUNTIF('🧾 RESUMO_IRT'!C8:C45,"José Fernando Manuel") -> 1 | D33: =SUMIF('🧾 RESUMO_IRT'!C8:C45,"José Fernando Manuel",'🧾 RESUMO_IRT'!E8:E45) -> 80000 | E33: =SUMIF('🧾 RESUMO_IRT'!C8:C45,"José Fernando Manuel",'🧾 RESUMO_IRT'!F8:F45) -> 5200 | F33: =SUMIF('🧾 RESUMO_IRT'!C8:C45,"José Fernando Manuel",'🧾 RESUMO_IRT'!G8:G45) -> 74800 | G33: =IF(COUNTIF('🧾 RESUMO_IRT'!C8:C45,"José Fernando Manuel")=0,"Sem registo",IF(SUMIF('🧾 RESUMO_IRT'!C8:C45,"José Fernando Manuel",'🧾 RESUMO_IRT'!I8:I45)<=0,"PAGO",IF(SUMIF('🧾 RESUMO_IRT'!C8:C45,"José Fernando Manuel",'🧾 RESUMO_IRT'!H8:H45)>0,"PARCIAL","EM ATRASO"))) -> EM ATRASO
B34: Walquiria Chissimo | C34: =COUNTIF('🧾 RESUMO_IRT'!C8:C45,"Walquiria Chissimo") -> 2 | D34: =SUMIF('🧾 RESUMO_IRT'!C8:C45,"Walquiria Chissimo",'🧾 RESUMO_IRT'!E8:E45) -> 100000 | E34: =SUMIF('🧾 RESUMO_IRT'!C8:C45,"Walquiria Chissimo",'🧾 RESUMO_IRT'!F8:F45) -> 6500 | F34: =SUMIF('🧾 RESUMO_IRT'!C8:C45,"Walquiria Chissimo",'🧾 RESUMO_IRT'!G8:G45) -> 93500 | G34: =IF(COUNTIF('🧾 RESUMO_IRT'!C8:C45,"Walquiria Chissimo")=0,"Sem registo",IF(SUMIF('🧾 RESUMO_IRT'!C8:C45,"Walquiria Chissimo",'🧾 RESUMO_IRT'!I8:I45)<=0,"PAGO",IF(SUMIF('🧾 RESUMO_IRT'!C8:C45,"Walquiria Chissimo",'🧾 RESUMO_IRT'!H8:H45)>0,"PARCIAL","EM ATRASO"))) -> EM ATRASO
B35: Félix Palau | C35: =COUNTIF('🧾 RESUMO_IRT'!C8:C45,"Félix Palau") -> 1 | D35: =SUMIF('🧾 RESUMO_IRT'!C8:C45,"Félix Palau",'🧾 RESUMO_IRT'!E8:E45) -> 104000 | E35: =SUMIF('🧾 RESUMO_IRT'!C8:C45,"Félix Palau",'🧾 RESUMO_IRT'!F8:F45) -> 6760 | F35: =SUMIF('🧾 RESUMO_IRT'!C8:C45,"Félix Palau",'🧾 RESUMO_IRT'!G8:G45) -> 97240 | G35: =IF(COUNTIF('🧾 RESUMO_IRT'!C8:C45,"Félix Palau")=0,"Sem registo",IF(SUMIF('🧾 RESUMO_IRT'!C8:C45,"Félix Palau",'🧾 RESUMO_IRT'!I8:I45)<=0,"PAGO",IF(SUMIF('🧾 RESUMO_IRT'!C8:C45,"Félix Palau",'🧾 RESUMO_IRT'!H8:H45)>0,"PARCIAL","EM ATRASO"))) -> EM ATRASO
B36: Marilda Augusto | C36: =COUNTIF('🧾 RESUMO_IRT'!C8:C45,"Marilda Augusto") -> 1 | D36: =SUMIF('🧾 RESUMO_IRT'!C8:C45,"Marilda Augusto",'🧾 RESUMO_IRT'!E8:E45) -> 10000 | E36: =SUMIF('🧾 RESUMO_IRT'!C8:C45,"Marilda Augusto",'🧾 RESUMO_IRT'!F8:F45) -> 650 | F36: =SUMIF('🧾 RESUMO_IRT'!C8:C45,"Marilda Augusto",'🧾 RESUMO_IRT'!G8:G45) -> 9350 | G36: =IF(COUNTIF('🧾 RESUMO_IRT'!C8:C45,"Marilda Augusto")=0,"Sem registo",IF(SUMIF('🧾 RESUMO_IRT'!C8:C45,"Marilda Augusto",'🧾 RESUMO_IRT'!I8:I45)<=0,"PAGO",IF(SUMIF('🧾 RESUMO_IRT'!C8:C45,"Marilda Augusto",'🧾 RESUMO_IRT'!H8:H45)>0,"PARCIAL","EM ATRASO"))) -> EM ATRASO
B37: José Monteiro | C37: =COUNTIF('🧾 RESUMO_IRT'!C8:C45,"José Monteiro") -> 1 | D37: =SUMIF('🧾 RESUMO_IRT'!C8:C45,"José Monteiro",'🧾 RESUMO_IRT'!E8:E45) -> 15000 | E37: =SUMIF('🧾 RESUMO_IRT'!C8:C45,"José Monteiro",'🧾 RESUMO_IRT'!F8:F45) -> 975 | F37: =SUMIF('🧾 RESUMO_IRT'!C8:C45,"José Monteiro",'🧾 RESUMO_IRT'!G8:G45) -> 14025 | G37: =IF(COUNTIF('🧾 RESUMO_IRT'!C8:C45,"José Monteiro")=0,"Sem registo",IF(SUMIF('🧾 RESUMO_IRT'!C8:C45,"José Monteiro",'🧾 RESUMO_IRT'!I8:I45)<=0,"PAGO",IF(SUMIF('🧾 RESUMO_IRT'!C8:C45,"José Monteiro",'🧾 RESUMO_IRT'!H8:H45)>0,"PARCIAL","EM ATRASO"))) -> EM ATRASO
B38: Domingos Ngando | C38: =COUNTIF('🧾 RESUMO_IRT'!C8:C45,"Domingos Ngando") -> 1 | D38: =SUMIF('🧾 RESUMO_IRT'!C8:C45,"Domingos Ngando",'🧾 RESUMO_IRT'!E8:E45) -> 10000 | E38: =SUMIF('🧾 RESUMO_IRT'!C8:C45,"Domingos Ngando",'🧾 RESUMO_IRT'!F8:F45) -> 650 | F38: =SUMIF('🧾 RESUMO_IRT'!C8:C45,"Domingos Ngando",'🧾 RESUMO_IRT'!G8:G45) -> 9350 | G38: =IF(COUNTIF('🧾 RESUMO_IRT'!C8:C45,"Domingos Ngando")=0,"Sem registo",IF(SUMIF('🧾 RESUMO_IRT'!C8:C45,"Domingos Ngando",'🧾 RESUMO_IRT'!I8:I45)<=0,"PAGO",IF(SUMIF('🧾 RESUMO_IRT'!C8:C45,"Domingos Ngando",'🧾 RESUMO_IRT'!H8:H45)>0,"PARCIAL","EM ATRASO"))) -> EM ATRASO
B41: 📋 NOTA DE CONFORMIDADE FISCAL: O valor total de IRT retido (célula D6) deve ser declarado à AGT até ao dia 20 do mês seguinte, através do formulário de Retenção na Fonte. O ISPTLO é responsável tributário pela retenção e entrega. Base legal: C.I.R.T. Lei nº 19/14, Art.º 67.
B43: BLOCO DE CONTROLO DOCUMENTAL
B44: Data de Elaboração: | C44: 01/05/2026
B45: Elaborado por: | C45: [Nome e Cargo — Tesouraria]
B46: Departamento: | C46: Departamento de Administração e Serviços Gerais — Tesouraria
B47: Aprovado por: | C47: [Nome, Grau, Cargo — Presidência]
B48: Data de Aprovação: | C48: [DD/MM/AAAA]
B49: Notificados: | C49: [Nomes dos Chefes de Departamento]
B50: Data de Notificação: | C50: [DD/MM/AAAA]
...
